Workbook

Sheet Portada
B10: Inventario del Portafolio de Aplicaciones (APM)
B12: Proyecto:
B13: Gestión del Portafolio de Aplicaciones — Modelo TIME de Gartner

Sheet README
B2: Gestión del Portafolio de Aplicaciones — Modelo TIME de Gartner
B3: Omnisys S.A. de C.V. · Gobierno de TI y Reportes
B5: 📋 Estructura del Libro de Trabajo
B6: Hoja | C6: Descripción
B7: Inventory | C7: Registro principal de APM — una fila por aplicación. Las celdas amarillas son para llenar.
B8: TIME Assessment | C8: Desglose de criterios de calificación por aplicación (Valor de Negocio + Salud Técnica).
B9: Dashboard | C9: KPIs calculados automáticamente: conteo por cuadrante TIME, costo total, riesgo de EOL.
B10: Lookups | C10: Listas de referencia utilizadas por los menús desplegables de validación de datos en todo el libro.
B12: ⬛ Modelo TIME de Gartner — Definición de Cuadrantes
B13: TOLERATE ⏸ | C13: Bajo Valor de Negocio + Alta Salud Técnica. Mantener en operación, minimizar el gasto; planear su retiro.
B14: INVEST ✅ | C14: Alto Valor de Negocio + Alta Salud Técnica. Incrementar la inversión, mejorar capacidades.
B15: MIGRATE 🔄 | C15: Alto Valor de Negocio + Baja Salud Técnica. Modernizar o reemplazar la plataforma; conservar la función.
B16: ELIMINATE ❌ | C16: Bajo Valor de Negocio + Baja Salud Técnica. Dar de baja lo antes posible; recuperar el costo de licencias/infraestructura.
B18: 🎨 Convención de Colores (hoja Inventory)
B19: Relleno amarillo | C19: Celda de entrada — dato a capturar por el dueño de TI / equipo APM.
B20: Texto negro | C20: Fórmula — no editar directamente.
B21: INVEST (verde) | C21: Disposición TIME calculada automáticamente a partir de las calificaciones en las columnas T y U.
B22: MIGRATE (naranja)
B23: TOLERATE (azul)
B24: ELIMINATE (rojo)
B25: Texto gris itálica | C25: Sin información — se revisó toda la documentación disponible y no se encontró ese dato para esa aplicación.
B26: Texto ámbar itálica
B28: 📊 Guía de Calificación — Valor de Negocio (1–5)
B29: 5 — Esencial | C29: Habilita directamente los ingresos o servicios de cara al cliente. No hay alternativa viable.
B30: 4 — Importante | C30: Soporte significativo a procesos. Es posible una solución temporal a corto plazo, pero costosa.
B31: 3 — Moderado | C31: Útil pero no crítico. Un proceso manual podría sustituirlo temporalmente.
B32: 2 — Marginal | C32: Usuarios o casos de uso limitados. Se traslapa con otras herramientas.
B33: 1 — Mínimo
B35: 🔧 Guía de Calificación — Salud Técnica (1–5)
B36: 5 — Excelente | C36: Arquitectura moderna, con soporte del proveedor, sin defectos conocidos, pruebas automatizadas.
B37: 4 — Bueno | C37: Estable, con soporte, deuda técnica menor.
B38: 3 — Aceptable | C38: Deuda técnica moderada, documentación limitada, despliegues manuales.
B39: 2 — Deficiente | C39: Plataforma envejecida, próxima a EOL, backlog de defectos considerable.
B40: 1 — Crítico
B42: 🔄 Cadencia de Gobierno
B43: Revisión Anual | C43: Reevaluación completa del portafolio. Actualizar todas las calificaciones, costos y disposiciones TIME.
B44: Revisión Trimestral | C44: Revisar las aplicaciones marcadas como Migrate o Eliminate. Actualizar EOL y estatus del proyecto.
B45: Alta de Nueva Aplicación | C45: Toda aplicación nueva debe registrarse en Inventory antes de su puesta en producción.
B46: Baja / Desmantelamiento | C46: Actualizar Status → Retiring, definir FEC_BAJA, retirar de la asignación de costos activa.
B49: 🔄 Criticidad Tec
...

Sheet Inventory
A2: ID | F2: Identidad de la Aplicación | Q2: Perfil Técnico | X2: Ciclo de Vida | AA2: Costos de Propiedad | AE2: Calificación APM | AI2: Gobierno | AL2: Riesgo y Cumplimiento | AP2: Valores TEC | AR2: Trazabilidad
A3: # | B3: Revisado | C3: VPAF/Centrales | D3: Decomiso | E3: ID Habilitador | F3: Habilitador (Aplicación) | G3: Descripción | H3: Producto_Componente:Title | I3: Producto_Componente | J3: Dueño Negocio (Product Owner) | K3: Responsable Técnico | L3: Responsable funcional | M3: Responsable de implementación | N3: Responsable de operación | O3: Responsable de soporte | P3: Proveedor | Q3: Nivel de customización | R3: Hosting | S3: Stack Tecnológico | T3: Dirección URL (PROD) | U3: Dirección URL (DEVL) | V3: Dirección URL (PPRD) | W3: Versión | X3: Primer Día Producción | Y3: Fin de Soporte | Z3: Usuarios Activos | AA3: Costo Licencias($) | AB3: Costo Infraestructura ($) | AC3: Soporte Anual ($) | AD3: Costo Total Anual ($) | AE3: Criticidad | AF3: Puntaje VN (1–5) | AG3: Puntaje ST (1–5) | AH3: Disposición TIME | AI3: Fecha Última Evaluación | AJ3: Próx Revisión | AK3: Estatus | AL3: Integraciones # | AM3: Clasificación de Datos | AN3: Etiquetas de Cumplimiento | AO3: Notas | AP3: Ecosistema | AQ3: Criticidad | AR3: Fuente de Información (SharePoint) | AS3: Confianza
A4: 1 | B4: Si | E4: 0109-HTI-001-TRXO | F4: SEA | G4: Gestión académica core: inscripciones, calificaciones, aprovisionamiento de usuarios; integra Salesforce, Canvas, Cypher, portales de registro y pago | H4: 15. Aprendizaje para el futuro | I4: ATV02. Gestión Académica | J4: Ernesto (solo nombre de pila; fuente: Correspondencia_Aplicaciones_APM_vs_Habilitadores.xlsx) | K4: Adrián Leonel Figueroa Ramírez | L4: claudia.arellano@tec.mx | M4: adrian.figueroa@tec.mx | N4: Adrian -> Uman Diez | O4: Adrian -> Uman Diez | P4: Oracle | Q4: Custom Development | R4: On-Premises | S4: Java (custom, equipo VPAF) | T4: Sin información | U4: Sin información | V4: Sin información | W4: Sin información | X4: Sin información | Y4: Sin información | Z4: 1,206 usuarios registrados en el portal de SEA (fuente: Usuarios SEA.xls). Desglose por tipo de perfil: Superusuario 622, Comercial 315, Líder de proyecto cerrados 100, Control escolar 75, Ingresos 39, Líder prospección 20, Egresos 12, Mercadotecnia 7, Vivencia 5, Prospección 4, Comercialización VIPEC 2, Logístico 2, Líder de proyecto abiertos 2, Prospección y comercial 1. | AA4: 0 | AB4: 0 | AC4: 0 | AD4: 0 | AE4: Mission Critical | AF4: 4 | AG4: 1 | AH4: =IF(AND(AF4>=3,AG4>=3),"Invest",IF(AND(AF4>=3,AG4<3),"Migrate",IF(AND(AF4<3,AG4>=3),"Tolerate","Eliminate"))) -> Migrate | AI4: 46227 | AJ4: 46592 | AK4: Active | AL4: 0 | AM4: Confidential | AN4: LFPDPPP | AO4: Gestión académica core: inscripciones, calificaciones, aprovisionamiento de usuarios; integra Salesforce, Canvas, Cypher, portales de registro y pago Hallazgo 21-sep-2026 (revisión profunda de archivos Excel de las carpetas conectadas): (1) Usuarios — 1,206 usuarios internos reales identificados con desglose por tipo de perfil (ver columna Usuarios Activos; fuente: Usuarios SEA.xls, carpeta Evidencia y platicas\SEA). (2) Alumnos — 57,702 registros reales de alumnos con acceso al sistema (fuente: AlumnosDatos.xlsx, Repositorio TD-Ecosistema Digital VPAF\Documentos Adicionales\SEA\SEA; solo se registra el conteo por tratarse de datos personales). (3) Modelo de datos — esquema real de 13 tablas de la base de datos (controlprogramas, datospersonales, controlprogramas_datosadicionales, datosmodulos, sesiones, asignacionprofesores, datosprofesores, profesoresgastosreales, pagotemporal, solicitudesrecibidas, controlalumnos, usuariounico, sincronizacionsistemas; fuente: TablasImportantesSEA.xlsx). (4) Procesos — 71 procesos/subprocesos funcionales de SEA (líneas U4P y U4O) y 29 mapeos técnicos (fuente: ATV Listado de procesos.xlsx). (5) Automatizaciones — 991 automatizaciones reales de Salesforce/VEC ligadas a SEA, cada una con su propio horario de ejecución (fuente: Automatizaciones flujos SF VEC (U4P y U4O).xlsx). Archivos 3-5 ubicados en Repositorio TD-Ecosistema Digital VPAF\Documentos Adicionales\SEA\Documentación Datos\Documentación SEA. | AP4: VEC | AQ4: 5 | AR4: SEA - carpeta principal | AS4: Confirmada
A5: 2 | B5: Si | E5: 5083-HTI-001-TRXO | F5: Middleware Comercial B2C | G5: Puente de datos / integración entre HubSpot, Salesforce, SEA y Looker; complementa leads y mueve registros | H5: Sin información | I5: Sin información | J5: Ernesto (solo nombre de pila; fuente: Correspondencia_Aplicaciones_APM_vs_Habilitadores.xlsx) | K5: Victor Rafael Tena | L5: victor.tena@tec.mx | M5: victor.tena@tec.mx | N5: victor.tena@tec.mx | O5: victor.tena@tec.mx | P5: AWS | Q5: Custom Development | R5: Cloud-PaaS | S5: AWS (RDS, S3); .Net C#, código sin login propio | T5: https://sso-saml.tec.mx | U5: https://sso-saml-dev.tec.mx | V5: https://sso-saml-qa.tec.mx | W5: Sin información | X5: Sin información | Y5: Sin información | Z5: De acuerdo a sesiones previas con Gobierno de datos, se tiene un estimado de 1,800,000 registros en RDS (leads desde 2019 a 2025) | AA5: 0 | AB5: 0 | AC5: 0 | AD5: 0 | AE5: Medium | AF5: 4 | AG5: 3 | AH5: =IF(AND(AF5>=3,AG5>=3),"Invest",IF(AND(AF5>=3,AG5<3),"Migrate",IF(AND(AF5<3,AG5>=3),"Tolerate","Eliminate"))) -> Invest | AI5: Sin información | AJ5: Sin información | AK5: Under Evaluation | AL5: Sin información | AM5: Restricted | AO5: Puente de datos / integración entre HubSpot, Salesforce, SEA y Looker; complementa leads y mueve registros | AP5: VEC | AQ5: 2 | AR5: No se encontró carpeta correspondiente en el índice de SharePoint | AS5: No encontrada
A6: 3 | B6: Si | E6: 0606-HTI-001-TRXC | F6: PASE | G6: Gestión de identidad y talento académico (expertos, candidatos); historial >115K registros | H6: 08. Colaboradores | I6: CLB05. Gestión de Talento | J6: Erik Sandoval Gutiérrez (esgutierrez@tec.mx) — Líder de Inteligencia Comercial | K6: Angelina Alarcón Romero | L6: iván Valdovinos | M6: Angelina Alarcón Romero | N6: anacopeliaalvarado@tec.mx -> Uman Diez | O6: esgutierrez@tec.mx -> Uman Diez | P6: Desarrollo interno ITESM–VPAF (Erik Sandoval Gutiérrez, L01260117); infraestructura en Azure | Q6: Custom Development | R6: Cloud-IaaS (Azure VM) | S6: ASP.NET / .NET Framework 4.8 sobre IIS 10; SQL Server 2012 + SSIS; librerías ClosedXML, Newtonsoft.Json, ZingChart, jQCloud, Font Awesome 4.7 | T6: https://pase.tec.mx/ITESM/Interno/Talento/Forms/01/REVEC_Login | U6: https://dev.iportafolio.app | V6: https://dev.iportafolio.app | W6: Componentes fuera de soporte del fabricante: SQL Server 2012 (12/07/2022) y Windows 10 (14/10/2025) | X6: Sin información | Y6: Sin información | Z6: Aproximadamente 5,000 expertos han dejado información en la plataforma. De esos, alrededor de 2,500 expertos han tenido participación activa en proyectos o evaluaciones. | AA6: 0 | AB6: 0 | AC6: 0 | AD6: 0 | AE6: Medium | AF6: 3 | AG6: 2 | AH6: =IF(AND(AF6>=3,AG6>=3),"Invest",IF(AND(AF6>=3,AG6<3),"Migrate",IF(AND(AF6<3,AG6>=3),"Tolerate","Eliminate"))) -> Migrate | AI6: 46251 | AJ6: 2027-08-17 | AK6: Active | AL6: 7 | AM6: Confidential | AN6: Datos personales (LFPDPPP): RFC, CURP, correo, teléfono, fotografía. Avisos de Privacidad Candidatos / Empleados / Educación Continua. Contraseñas cifradas en BD. Sin SSO institucional. | AO6: Gestión de identidad y talento académico (expertos, candidatos); historial >115K registros Ambientes: solo PROD. No existen DEVL, PPRD ni Capacitación (Arquitectura del Sistema §6, V1.9 del 03-Jul-2024). URL corregida a pase.tec.mx. Las direcciones iportafolio.app pertenecen a otro habilitador (responsable Angelina Alarcón), no a PASE. Infraestructura: dos instancias en Azure VM (app IIS + BD SQL Server 2012 con SSIS). Riesgo de obsolescencia tecnológica. Autenticación nativa confirmada por documento oficial: correo + contraseña cifrada en BD, para internos y expertos externos. No usa Azure AD. Base de datos: 48 stored procedures en 12 categorías, 5 de criticidad alta y 3 ligados a APIs públicas (corte 25/05/2026). Integración pendiente PASE → Drupal (INT-R1-002 v2.2, junio 2026): riesgo D6 BLOQUEANTE por acceso de red a SQL Server. Contacto: Erik Sandoval. Las 7 integraciones son: Qualtrics (mensual vía SSIS), archivo GyT de categorización (diario), Google Maps API, API U4P Semblanza hacia maestriasydiplomados.tec.mx, API iPortafolio, Territorium (enlace académico) y CRM Empresas. | AP6: VEC | AQ6: 3 | AR6: No se encontró carpeta correspondiente en el índice de SharePoint | AS6: No encontrada
A7: 4 | B7: Si | E7: 0605-HIT-001-TRXC | F7: iPortafolio | G7: Sistema con IA generativa para construcción de propuestas comerciales; consume Salesforce y PASE | H7: 15. Aprendizaje para el futuro | I7: ATV03-1. Atracción y Venta | J7: Ernesto (solo nombre de pila; fuente: Correspondencia_Aplicaciones_APM_vs_Habilitadores.xlsx) | K7: Angelina Alarcón Romero | L7: angelina.alarcon@tec.mx | M7: angelina.alarcon@tec.mx | N7: luis.chitala@tec.mx | O7: luis.chitala@tec.mx | P7: Microsoft Azure | Q7: Custom Development | R7: Hybrid | S7: Django + Azure AD | T7: https://iportafolio.app | U7: https://dev.iportafolio.app | V7: https://dev.iportafolio.app | W7: Sin información | X7: Sin información | Y7: Sin información | Z7: Actualmente 121 usuarios (Asesores de organizaciones y equipo de la VEC). 1500 propuestas acumuladas en dos años 20 a 25 propuestas nuevas por quincena | AA7: 0 | AB7: 0 | AC7: 0 | AD7: 0 | AE7: Medium | AF7: 3 | AG7: 4 | AH7: =IF(AND(AF7>=3,AG7>=3),"Invest",IF(AND(AF7>=3,AG7<3),"Migrate",IF(AND(AF7<3,AG7>=3),"Tolerate","Eliminate"))) -> Invest | AI7: Sin información | AJ7: Sin información | AK7: Active | AL7: Sin información | AM7: Confidential | AO7: Sistema con IA generativa para construcción de propuestas comerciales; consume Salesforce y PASE | AP7: VEC | AQ7: 3 | AR7: No se encontró carpeta correspondiente en el índice de SharePoint | AS7: No encontrada
A8: 5 | B8: Si | E8: 0613-HTI-001-TRXO | F8: Ticket DAP | G8: Levantamiento y gestión de tickets internos de soporte operativo; integrado con Salesforce y SEA | H8: 15. Aprendizaje para el futuro | I8: ATV01. Compra y Pago | J8: Laura (solo nombre de pila; fuente: Correspondencia_Aplicaciones_APM_vs_Habilitadores.xlsx) | K8: Víctor Rafael Tena Ojeda | L8: victor.tena@tec.mx | M8: victor.tena@tec.mx | N8: victor.tena@tec.mx | O8: victor.tena@tec.mx | P8: Desarrollo interno (Tec de Monterrey) | Q8: Custom Development | R8: Cloud-SaaS | S8: Python (FastAPI) sobre Docker | T8: https://www.tecdap.net/help | U8: https://www.tecdap.net/help_dev | V8: Sin información | W8: Sin información | X8: Sin información | Y8: Sin información | Z8: 160.0 | AA8: 0 | AB8: 0 | AC8: 0 | AD8: 0 | AE8: Medium | AF8: 3 | AH8: =IF(AND(AF8>=3,AG8>=3),"Invest",IF(AND(AF8>=3,AG8<3),"Migrate",IF(AND(AF8<3,AG8>=3),"Tolerate","Eliminate"))) -> Migrate | AI8: Sin información | AJ8: Sin información | AK8: Active | AL8: Sin información | AM8: Confidential | AN8: Sin información | AO8: Levantamiento y gestión de tickets internos de soporte operativo; integrado con Salesforce y SEA | AP8: VEC | AQ8: 3 | AR8: No se encontró carpeta correspondiente en el índice de SharePoint | AS8: No encontrada
A9: 6 | B9: Si | E9: 0495-HTI-001-SDMC | F9: Service Now (ex CASEC) | G9: Mesa de servicio institucional, atención de tickets de colaboradores | H9: Sin información | I9: Sin información | J9: alan.bustamante@tec.mx | K9: Cada dueño -> Hoy se centralizan con Blanca Mata | L9: Miguel Burgoin / Blanca Mata | M9: jebreyes@tec.mx | N9: josemiguel@tec.mx | O9: oscar.rdz@tec.mx | P9: ServiceNow | Q9: Commercial Off-the-Shelf | R9: Cloud-SaaS | S9: ServiceNow (federado MiTec) | T9: Sin información | U9: Sin información | V9: Sin información | W9: Sin información | X9: Sin información | Y9: Sin información | Z9: Más de 300 usuarios de la VPAF que tienen acceso a levantar tickets y cerca de 30 analistas que los resuelve | AA9: 0 | AB9: 0 | AC9: 0 | AD9: 0 | AE9: Medium | AF9: 3 | AG9: 2 | AH9: =IF(AND(AF9>=3,AG9>=3),"Invest",IF(AND(AF9>=3,AG9<3),"Migrate",IF(AND(AF9<3,AG9>=3),"Tolerate","Eliminate"))) -> Migrate | AI9: Sin información | AJ9: Sin información | AK9: Active | AL9: Sin información | AM9: Restricted | AN9: Sin información | AO9: Mesa de servicio institucional, atención de tickets de colaboradores | AP9: VEC | AQ9: 3 | AR9: DIR-015 - TecBot VPAF-Service Now (solo integración con TecBot) | AS9: Parcial / relacionada
A10: 7 | B10: Si | E10: 5149-VPA-001-BIPC | F10: Sistema de Rúbricas / Perfilador | G10: Perfilador de prospectos antes de inscripción; ~5,000 aprendedores hacen la prueba | H10: Sin información | I10: Sin información | J10: nlopeznegrete@tec.mx | K10: Víctor Rafael Tena Ojeda | L10: Víctor Rafael Tena Ojeda | M10: Víctor Rafael Tena Ojeda | N10: Víctor Rafael Tena Ojeda | O10: Víctor Rafael Tena Ojeda | P10: Google + Azure | Q10: Custom Development | R10: Hybrid | S10: PHP + MySQL (auth Google + Azure) | T10: Sin información | U10: Sin información | V10: Sin información | W10: Sin información | X10: Sin información | Y10: Sin información | Z10: 10 usuarios que obtienen información. 5 mil aprendedores que hacen la prueba (usuarios que agregan información). | AA10: 0 | AB10: 0 | AC10: 0 | AD10: 0 | AE10: Low | AF10: 1 | AG10: 2 | AH10: =IF(AND(AF10>=3,AG10>=3),"Invest",IF(AND(AF10>=3,AG10<3),"Migrate",IF(AND(AF10<3,AG10>=3),"Tolerate","Eliminate"))) -> Eliminate | AI10: Sin información | AJ10: Sin información | AK10: Active | AL10: Sin información | AM10: Sin información | AO10: ⚠ Verificar: ID Habilitador también asignado a fila 47 ("Buscador / Search Bar"). | AP10: VEC | AQ10: 2 | AR10: No se encontró carpeta correspondiente en el índice de SharePoint | AS10: No encontrada
A11: 8 | B11: Si | E11: Sin información | F11: MICASA | G11: Sitio informativo para profesores/expertos; concentra recursos y comunicaciones | H11: Sin información | I11: Sin información | J11: Sin información | K11: Ana Copelia Alvarado Zepeda | L11: Ana Copelia Alvarado Zepeda | M11: Ana Copelia Alvarado Zepeda | N11: Ana Copelia Alvarado Zepeda | O11: Ana Copelia Alvarado Zepeda | P11: Google | Q11: Custom Development | R11: Cloud-PaaS | S11: Google Sites | T11: Sin información | U11: Sin información | V11: Sin información | W11: Sin información | X11: Sin información | Y11: Sin información | Z11: N/A | AA11: 0 | AB11: 0 | AC11: 0 | AD11: 0 | AE11: Low | AF11: 2 | AH11: =IF(AND(AF11>=3,AG11>=3),"Invest",IF(AND(AF11>=3,AG11<3),"Migrate",IF(AND(AF11<3,AG11>=3),"Tolerate","Eliminate"))) -> Eliminate | AI11: Sin información | AJ11: Sin información | AK11: Retiring | AL11: Sin información | AM11: Internal | AN11: Sin información | AO11: Sitio informativo para profesores/expertos; concentra recursos y comunicaciones | AP11: VEC | AQ11: 2 | AR11: No se encontró carpeta correspondiente en el índice de SharePoint | AS11: No encontrada
A12: 9 | B12: Si | E12: Sin información | F12: Legismex | G12: Sitio del centro de tecnologías para el desarrollo sostenible, contenidos jurídicos/normativos para empresas | H12: Sin información | I12: Sin información | J12: Sin información | K12: María Antonia Garza Jasso | L12: María Antonia Garza Jasso | M12: María Antonia Garza Jasso | N12: María Antonia Garza Jasso | O12: María Antonia Garza Jasso | P12: Sin información | Q12: Custom Development | R12: Sin información | S12: Front en servidor externo (tecnología por confirmar) | T12: Sin información | U12: Sin información | V12: Sin información | W12: Sin información | X12: Sin información | Y12: Sin información | Z12: No especificado, pero limitado a empresas registradas manualmente 230 empresas y son entre 850 y 900 usuarios | AA12: 0 | AB12: 0 | AC12: 0 | AD12: 0 | AE12: Low | AF12: 2 | AG12: 4 | AH12: =IF(AND(AF12>=3,AG12>=3),"Invest",IF(AND(AF12>=3,AG12<3),"Migrate",IF(AND(AF12<3,AG12>=3),"Tolerate","Eliminate"))) -> Tolerate | AI12: Sin información | AJ12: Sin información | AK12: Active | AL12: Sin información | AM12: Sin información | AN12: Sin información | AO12: Sitio del centro de tecnologías para el desarrollo sostenible, contenidos jurídicos/normativos para empresas | AP12: VEC | AQ12: 2 | AR12: No se encontró carpeta correspondiente en el índice de SharePoint | AS12: No encontrada
A13: 10 | B13: Si | E13: 0238-HTI-001-MKAC | F13: HubSpot | G13: Marketing automation y campañas; centraliza leads de U4O y U4P; integra Middleware y Salesforce | H13: Sin información | I13: Sin información | J13: Laura (solo nombre de pila; fuente: Correspondencia_Aplicaciones_APM_vs_Habilitadores.xlsx) | K13: Carlos Franco | L13: Carlos Franco | M13: Israel Martinez israel@tec.mx | N13: Israel Martinez israel@tec.mx | O13: Israel Martinez israel@tec.mx | P13: HubSpot | Q13: SaaS | R13: Cloud-SaaS | S13: HubSpot (SaaS, federado) | T13: Sin información | U13: Sin información | V13: Sin información | W13: Sin información | X13: Sin información | Y13: Sin información | Z13: Usuarios internos -U4O: 4 -U4P: 20 | AA13: 0 | AB13: 0 | AC13: 0 | AD13: 0 | AE13: High | AF13: 4 | AG13: 3 | AH13: =IF(AND(AF13>=3,AG13>=3),"Invest",IF(AND(AF13>=3,AG13<3),"Migrate",IF(AND(AF13<3,AG13>=3),"Tolerate","Eliminate"))) -> Invest | AI13: Sin información | AJ13: Sin información | AK13: Active | AL13: Sin información | AM13: Sin información | AN13: Sin información | AO13: Marketing automation y campañas; centraliza leads de U4O y U4P; integra Middleware y Salesforce | AP13: VEC | AQ13: 4 | AR13: Notificaciones por HubSpot (solo diseños de notificación) | AS13: Parcial / relacionada
A14: 11 | B14: Si | E14: 0027-HTI-001-CRMC | F14: Salesforce | G14: CRM institucional; seguimiento de leads, oportunidades y pipeline comercial; integra Middleware, SEA, HubSpot, PASE | H14: Sin información | I14: Sin información | J14: Ulises (solo nombre de pila; fuente: Correspondencia_Aplicaciones_APM_vs_Habilitadores.xlsx) | K14: Jose Luis Torres (externo) | L14: B2C - Yolanda Magaña B2B - Larisa Díaz / Erik Sandoval | M14: Guillermo Lopez | N14: 1er nivel - Guillermo Lopez 2do nivel - equipo central | O14: 1er nivel - Guillermo Lopez 2do nivel - equipo central | P14: Salesforce | Q14: SaaS | R14: Cloud-SaaS | S14: Salesforce (SaaS, federado) | T14: Sin información | U14: Sin información | V14: Sin información | W14: Sin información | X14: Sin información | Y14: Sin información | Z14: Se tiene registro de 415 activos. | AA14: 0 | AB14: 0 | AC14: 0 | AD14: 0 | AE14: Mission Critical | AF14: 5 | AG14: 2 | AH14: =IF(AND(AF14>=3,AG14>=3),"Invest",IF(AND(AF14>=3,AG14<3),"Migrate",IF(AND(AF14<3,AG14>=3),"Tolerate","Eliminate"))) -> Migrate | AI14: Sin información | AJ14: Sin información | AK14: Active | AL14: Sin información | AM14: Sin información | AN14: Sin información | AO14: CRM institucional; seguimiento de leads, oportunidades y pipeline comercial; integra Middleware, SEA, HubSpot, PASE | AP14: VEC | AQ14: 5 | AR14: JOB-012 - SEA-Pulsar-Salesforce (solo flujo de integración) | AS14: Parcial / relacionada
A15: 12 | E15: 0034-HTI-001-ERPC | F15: SAP (verificar información con Lulu Ayala) | G15: Sistema financiero institucional | H15: 04. Finanzas | I15: FNC05. Información financiera y fiscal | J15: Ulises (solo nombre de pila; fuente: Correspondencia_Aplicaciones_APM_vs_Habilitadores.xlsx) | K15: El soporte y gestión técnica se realiza por área central de TI, mediante tickets para aprovisionamiento y ajustes. | L15: Maria Amelia Estrada | M15: jebreyes@tec.mx | N15: alonso.valenzuela@tec.mx | O15: colivar@tec.mx | P15: SAP | Q15: Commercial Off-the-Shelf | R15: Cloud-SaaS | S15: SAP (federado, gestión central Tec) | T15: Sin información | U15: Sin información | V15: Sin información | W15: Sin información | X15: Sin información | Y15: Sin información | Z15: No se cuenta con un volumen específico, pero se cuenta con información desde el 2006. | AA15: 0 | AB15: 0 | AC15: 0 | AD15: 0 | AE15: Mission Critical | AF15: 5 | AG15: 4 | AH15: =IF(AND(AF15>=3,AG15>=3),"Invest",IF(AND(AF15>=3,AG15<3),"Migrate",IF(AND(AF15<3,AG15>=3),"Tolerate","Eliminate"))) -> Invest | AI15: Sin información | AJ15: Sin información | AK15: Active | AL15: Sin información | AM15: Sin información | AN15: Sin información | AO15: Sistema financiero institucional | AP15: VEC | AQ15: 5 | AR15: No se encontró carpeta correspondiente en el índice de SharePoint | AS15: No encontrada
A16: 13 | E16: 0222-HTI-001-SISO | F16: Banner (verificar información con Lulu Ayala) | G16: Procesos de pago automatizados (uso heredado, conexión institucional) | H16: 16. Línea de Servicio | I16: HT03. Banner | J16: María Alejandra Rohrman Ramos (ale_rohrman@tec.mx) | K16: aoropeza@tec.mx | L16: sandra.garza@tec.mx | M16: aoropeza@tec.mx | N16: antonio.jimenez@tec.mx | O16: oscar.rdz@tec.mx | P16: Ellucian Banner | Q16: SaaS | R16: Cloud-SaaS | S16: Ellucian Banner (gestión central Tec) | T16: https://adminpages.tec.mx/applicationNavigator | U16: Sin información | V16: Sin información | W16: Sin información | X16: Sin información | Y16: Sin información | Z16: Sin información | AA16: 0 | AB16: 0 | AC16: 0 | AD16: 0 | AE16: High | AF16: 4 | AG16: 4 | AH16: =IF(AND(AF16>=3,AG16>=3),"Invest",IF(AND(AF16>=3,AG16<3),"Migrate",IF(AND(AF16<3,AG16>=3),"Tolerate","Eliminate"))) -> Invest | AI16: 46251 | AJ16: 46616 | AK16: Active | AL16: 7 | AM16: Restricted | AN16: Sistema institucional gestionado centralmente; datos financieros de cobranza estudiantil. Acceso federado. | AO16: Procesos de pago automatizados (uso heredado, conexión institucional) Banner es donde se lleva la cuenta del cliente: registra el cargo, el pago y la compensación, y guarda el código de servicio con el que se arma la factura. Tres fuentes confirman este uso. El aplicativo que corresponde a esta descripción es el módulo de cuentas por cobrar, no el de estudiantes que se le había ligado. Hay que corregir el identificador. Se conecta con siete sistemas: Gestor de Pagos, VTEX, Portal de Registro y Pago, MDM Central, SAP, el facturador Interfactura y SEA. Sus catálogos los administra Tech Services: códigos de detalle de cuatro caracteres, uno por moneda, y códigos de servicio de seis caracteres. Problema conocido: las ventas del día se registran en un identificador genérico y no en la cuenta del aprendedor, por eso la factura sale primero a un RFC genérico y luego se refactura. A quién preguntar: María Alejandra Rohrman lleva la facturación, Elva Rivas la administración tecnológica, Zulema Pargas los catálogos y Armando Contreras es el dueño funcional de educación continua. El Tec tiene marcado que falta identificar al dueño institucional. No aparece en el inventario de metadatos de la VPAF. Siguen pendientes costos, ambientes, versión y fechas. | AP16: VEC | AQ16: 4 | AR16: No se encontró carpeta correspondiente en el índice de SharePoint | AS16: No encontrada
A17: 14 | E17: Sin información | F17: Looker Studio | G17: Tableros de visualización para usuarios institucionales (@tec.mx); consume datos procesados de Middleware | H17: 10. Plataforma de Datos (propuesta) | I17: DP01. TEC.data (propuesta) | J17: Sin dueño formal asignado; usuarios registrados en VPAF: Andrés Segura (andres.pantoja@tec.mx), Erik Sandoval (esgutierrez@tec.mx), Victor Tena (victor.tena@tec.mx), Copelia Alvarado (anacopeliaalvarado@tec.mx) | K17: El responsable técnico es José Andrés Segura Pantoja, | L17: Sin información | M17: Sin información | N17: Sin información | O17: Sin información | P17: Google | Q17: SaaS | R17: Cloud-SaaS | S17: Google Looker Studio | T17: https://lookerstudio.google.com | U17: No aplica (SaaS sin ambientes) — coherente con S17 y T17, que ya dicen "No aplica" | V17: No aplica | W17: No aplica | X17: No aplica | Y17: No aplica (servicio SaaS de Google sin fecha de fin de soporte contractual) | Z17: El acceso a los tableros se limita a usuarios institucionales con correos del Tec, principalmente personal de marketing y ventas. No se menciona una cifra exacta, pero se infiere que el volumen es reducido y restringido al personal interno, sin participación de usuarios externos. | AA17: 0 | AB17: 0 | AC17: 0 | AD17: 0 | AE17: Medium | AF17: 3 | AG17: 4 | AH17: =IF(AND(AF17>=3,AG17>=3),"Invest",IF(AND(AF17>=3,AG17<3),"Migrate",IF(AND(AF17<3,AG17>=3),"Tolerate","Eliminate"))) -> Invest | AI17: 46251 | AJ17: 46616 | AK17: Active | AL17: 2 | AM17: Confidential | AN17: Acceso restringido a usuarios institucionales @tec.mx. Federado y gestionado por Tec de Monterrey. Datos de negocio en tableros; sin datos personales sensibles. | AO17: Tableros de visualización para usuarios institucionales (@tec.mx); consume datos procesados de Middleware Looker no está dado de alta en la wiki de habilitadores ni en el inventario de metadatos de la VPAF, pero sí aparece en la arquitectura del ecosistema dentro de la capa de analítica, junto con Power BI y el Data Warehouse del Tec. El propio Tec lo reconoce sin dueño: en su listado lo registra con cuatro personas etiquetadas como usuarios, no como administradores. Son Andrés Segura, Erik Sandoval, Victor Tena y Copelia Alvarado. El primero coincide con el responsable técnico ya capturado. La clasificación de producto es propuesta nuestra, tomada del Data Warehouse del Tec, porque este aplicativo no tiene una asignada. Hay al menos un tablero en producción, el de precios de colegiatura que usa el área de Inscripciones, y está siendo reemplazado por uno nuevo en Power BI con fecha objetivo del 31 de julio de 2026. Se marcó no aplica en versión, fin de soporte y ambientes de desarrollo porque es un servicio en la nube sin versiones ni ambientes propios. El costo en cero está confirmado: la documentación del tablero de colegiaturas dice que no representa costos adicionales. Falta confirmar si hay contratación de la versión de paga. La información del tablero revisado no está catalogada como confidencial, por eso se clasificó como interna. Punto a reportar: hay tableros consumiendo datos institucionales sin registro formal ni dueño. Existe además una regla del ecosistema que separa lo transaccional de lo analítico, y esta herramienta no debe consultar directamente los sistemas de operación. | AP17: VEC | AQ17: 3 | AR17: No se encontró carpeta correspondiente en el índice de SharePoint | AS17: No encontrada
A18: 15 | E18: 0035-TC-002-ERPC | F18: Success Factors | G18: LMS para encuestas y cursos a instructores; ~5,800 usuarios activos | H18: 08. Colaboradores | I18: CLB05. Gestión de Talento | J18: Elva Rivas (elva@tec.mx) | K18: Elva Rivas Ledezma, quien gestiona la operación. El soporte técnico institucional se brinda a través del equipo de TI (Tecnologías de Información). | L18: rogelio.marquez@tec.mx | M18: jcarranz@tec.mx | N18: Elva Rivas (elva@tec.mx) — el registro VPAF la marca como quien gestiona la operación, y H18 ya lo dice así | O18: saranaomi.espana@tec.mx | P18: SAP | Q18: Commercial Off-the-Shelf | R18: Cloud-SaaS | S18: SAP SuccessFactors | T18: Sin información | U18: No aplica (SaaS institucional sin ambiente accesible a VPAF) | V18: No aplica (SaaS institucional sin ambiente accesible a VPAF) | W18: No aplica (SaaS con actualización continua del proveedor) | X18: Sin información | Y18: Sujeto a contrato institucional SAP; no gestionado por VPAF | Z18: -Alumnos:5791 -Profesores -Admin Actualmente se tienen 5,791 usuarios activos, se tiene limite de 10,000 licencias para todos los usuarios. Usuarios nominales identificados en "Aplicaciones Funcionales Vivencia.xlsx" (hoja Hoja1 + hoja Equipo Vivencia), carpeta de evidencia "Evidencia y platicas/Herramientas Vivencia": L03533260 - Hernandez Rodriguez Arlette; L03536134 - Arce Estrada Cristina; L03133597 - Mendoza De Leon Estefania; L03132444 - De la Cruz Ascencio Marcela; L01406546 - Alfredo Ramirez Mejia; L00480574 - Eva Alvarez Sigrist. Esta es informacion adicional/complementaria a la cifra agregada de 5,791 usuarios ya documentada (equipo Vivencia con acceso confirmado a Success Factor para seguimiento al proceso de aprendizaje del aprendedor); no la sustituye. | AA18: 0 | AB18: 0 | AC18: 0 | AD18: 0 | AE18: Medium | AF18: 3 | AG18: 3 | AH18: =IF(AND(AF18>=3,AG18>=3),"Invest",IF(AND(AF18>=3,AG18<3),"Migrate",IF(AND(AF18<3,AG18>=3),"Tolerate","Eliminate"))) -> Invest | AI18: 46251 | AJ18: 2027-08-17 | AK18: Active | AL18: 1 | AM18: Confidential | AN18: Datos personales de colaboradores e instructores (LFPDPPP). Acceso federado institucional, gestionado por Tec de Monterrey. Contrato y cumplimiento a cargo del área central. | AO18: LMS para encuestas y cursos a instructores; ~5,800 usuarios activos Success Factors se usa para encuestas y cursos a instructores. Elva Rivas, Líder de Administración Tecnológica, aparece como administradora y como dueña de los datos en dos fuentes distintas. Su líder es Aramis Arturo Meza Lara. El acceso es federado y la plataforma la gestiona Tec de Monterrey. Los datos viven en la base de datos de Success Factors. Contradicción a resolver: el documento de arquitectura dice que opera independiente del sistema académico, pero el inventario de metadatos indica que sus datos se actualizan al actualizar SEA. Hay que aclarar si existe esa conexión. Por ahora se contó una integración. Guarda datos personales sensibles: género, domicilio, puesto y división organizacional. Por eso se clasificó como confidencial. La suite tiene otros cinco módulos. Hay que definir si el inventario se refiere solo al de capacitación o a toda la suite. Está implementado en cuatro instituciones del sistema Tec, pero nuestro alcance es solo Tec de Monterrey. La wiki no registra responsable de operación. Siguen pendientes costos, ambientes, versión y fechas. | AP18: VEC | AQ18: 3 | AR18: No se encontró carpeta correspondiente en el índice de SharePoint | AS18: No encontrada
A19: 16 | B19: Si | D19: Si | E19: 0017-HTI-001-LMSC | F19: Canvas (ya no se utiliza) | G19: LMS principal para programas U4O y U4P; ~4,750 usuarios; integrado con SEA | H19: 01. Aprendizaje y Enseñanza | I19: TL01. Plataformas de Aprendizaje y Evaluación | J19: Israel Martínez Frías (israel.martinez@tec.mx) | K19: Israel Martínez Frías | L19: bsaldivar@tec.mx | M19: ctvalenzuela@tec.mx | N19: alejandro.ramos@tec.mx | O19: oscar.rdz@tec.mx | P19: Instructure Canvas | Q19: SaaS | R19: Cloud-SaaS | S19: Instructure Canvas | T19: https://educacioncontinuatec.instructure.com | U19: No aplica (SaaS sin ambiente de desarrollo gestionado por VPAF) | V19: No aplica (SaaS sin ambiente de preproducción gestionado por VPAF) | W19: No aplica (SaaS con actualización continua del proveedor Instructure) | X19: Sin información | Y19: Sujeto a contrato con Instructure; pendiente de confirmar con el administrador del contrato | Z19: 4750.0 | AA19: 0 | AB19: 0 | AC19: 0 | AD19: 0 | AE19: High | AF19: 0 | AG19: 0 | AH19: =IF(AND(AF19>=3,AG19>=3),"Invest",IF(AND(AF19>=3,AG19<3),"Migrate",IF(AND(AF19<3,AG19>=3),"Tolerate","Eliminate"))) -> Eliminate | AI19: 46251 | AJ19: 46616 | AK19: Active | AL19: 2 | AM19: Confidential | AN19: Datos personales y académicos de alumnos (LFPDPPP): matrícula, calificaciones y evidencias de aprendizaje. Plataforma SaaS externa con acuerdo institucional. | AO19: LMS principal para programas U4O y U4P; ~4,750 usuarios; integrado con SEA Canvas es la plataforma donde el profesor imparte y evalúa, para los cursos U4P y U4O. Israel Martínez Frías aparece como administrador y dueño de los datos en dos fuentes distintas. Los datos se almacenan en la nube de Canvas administrada por Instructure. El acceso es por SSO. Se conecta con el sistema académico, de donde recibe cursos y personas, y con Banner, que provisiona usuarios de forma automática usando el PIDM como identificador. El paso de calificaciones de regreso al sistema académico lo hace Control Escolar a mano: no hay integración automática. Es una deuda técnica ya reconocida por el Tec. Hay varias instancias. La dirección que se capturó es la de Educación Continua, cuyo dominio amigable es miformacioncontinua.tec.mx. Existen también tec.instructure.com y experiencia21.tec.mx. Hay que confirmar a cuál se refiere el inventario. Existe un reporte de licenciamiento dentro de Canvas. De ahí se puede sacar el número real de usuarios activos. Dato de costo de referencia, de 2019: cada instancia adicional cuesta 1,500 dólares al año. No es el costo total de licenciamiento y hay que actualizarlo. La wiki no tiene dirección de producción para el módulo principal. El módulo de calificaciones sí: https://admincursos.tec.mx/grades | AP19: VEC | AQ19: 4 | AR19: No se encontró carpeta correspondiente en el índice de SharePoint | AS19: No encontrada
A20: 17 | B20: Si | E20: 5169-VPA-001-TRXC | F20: Cypher Learning | G20: LMS para cursos U4O/U4P; ~14,887 asientos; integrado con SEA | H20: 18. APF Ecosistema Digital | I20: ECD03- APF Vivencia y Gestión del Aprendizaje | J20: Luis (solo nombre de pila; fuente: Correspondencia_Aplicaciones_APM_vs_Habilitadores.xlsx) Dato de contrato (Template contratos_11Sep26_V1.xlsx, inventario SAM/HAM en ServiceNow de Uman Amaru Diez Molina, carpeta 'Evidencia y platicas/Uman Diez'): Business Owner registrado = Claudia Arellano Arciga; Vendor = CYPHER LEARNING Inc.; Contract Administrator = Jorge Alberto González López; Approver = Carmen Isabel Reyes Peraza. Pendiente reconciliar con el nombre 'Luis' ya registrado como dueño de negocio desde otra fuente (Correspondencia_Aplicaciones_APM_vs_Habilitadores.xlsx). | K20: Israel Martínez Frías. Contacto adicional confirmado en sesión S-037 (21? 03-sep-2026): Silvino Muñoz Caracas (silvino.munoz@tec.mx). | L20: hcolon@tec.mx | M20: israel.martinez@tec.mx | N20: israel.martinez@tec.mx | O20: israel.martinez@tec.mx | P20: Cypher Learning (LXP/LMS) | Q20: SaaS | R20: Cloud-SaaS | S20: Cypher Learning (LXP/LMS) | T20: https://educacioncontinua.tec.mx/ | U20: http://tecsandbox.neolms.com/ | V20: Sin información | W20: Sin información | X20: Sin información | Y20: Sin información | Z20: 14,887 es un sistema de asientos. | AA20: 0 | AB20: 0 | AC20: 0 | AD20: 0 | AE20: High | AF20: 4 | AG20: 2 | AH20: =IF(AND(AF20>=3,AG20>=3),"Invest",IF(AND(AF20>=3,AG20<3),"Migrate",IF(AND(AF20<3,AG20>=3),"Tolerate","Eliminate"))) -> Migrate | AI20: Sin información | AJ20: Sin información | AK20: Active | AL20: Sin información | AM20: Confidential | AN20: Sin información | AO20: LMS para cursos U4O/U4P; ~14,887 asientos; integrado con SEA Hallazgo sesión S-037 (03-sep-2026): actualmente Cypher Learning opera principalmente mediante cargas manuales; las integraciones con otras plataformas están en proceso de habilitación vía APIs. Forma parte de los 5 aplicativos prioritarios de la iniciativa (junto con PASE, SEA, VTEX/Ecommerce y Portal Unificado). | AP20: VEC | AQ20: 4 | AR20: A001-C01-Plataforma de aprendizaje cypher | AS20: Parcial / relacionada
A21: 18 | B21: Si | E21: 5057-HTI-001-BIPC | F21: Qualtrics | G21: Encuestas NPS, evaluación de programas e instructores; ~2,500 usuarios | H21: Sin información | I21: Sin información | J21: Luis (solo nombre de pila; fuente: Correspondencia_Aplicaciones_APM_vs_Habilitadores.xlsx) | K21: Ricardo Flores | L21: meavil@tec.mx | M21: mm.morales@tec.mx | N21: Sin información | O21: Sin información | P21: Qualtrics (SaaS, parcialmente federado) | Q21: SaaS | R21: Cloud-SaaS | S21: Qualtrics (SaaS, parcialmente federado) | T21: https://itesm.co1.qualtrics.com/ | U21: Sin información | V21: Sin información | W21: Sin información | X21: Sin información | Y21: Sin información | Z21: Actualmente, alrededor de 2,500 | AA21: 0 | AB21: 0 | AC21: 0 | AD21: 0 | AE21: Medium | AF21: 3 | AG21: 3 | AH21: =IF(AND(AF21>=3,AG21>=3),"Invest",IF(AND(AF21>=3,AG21<3),"Migrate",IF(AND(AF21<3,AG21>=3),"Tolerate","Eliminate"))) -> Invest | AI21: Sin información | AJ21: Sin información | AK21: Active | AL21: SEA (MySQL) ↔ Qualtrics ↔ SharePoint: automatización real documentada "Reporte Módulos Qualtrics v2" (Bizagi Modeler v1.0, autor dora.marquez, 08-abr-2025) — SEA se conecta a Qualtrics con credenciales propias, descarga reporte CSV, lo transforma, actualiza archivo maestro en SharePoint, genera Excel procesado, envía correo a destinatarios y archiva históricos; incluye manejo de errores por correo. Fuente: Repositorio TD-Ecosistema Digital VPAF\Documentos Adicionales\SEA\Documentación Datos\Documentación SEA\Automatizaciones\Documentación funcional\Automatización Reportes de Módulos Qualtrics v2.pdf (hallazgo de la décima séptima pasada, 17-sep-2026). | AM21: Sin información | AN21: Sin información | AO21: Encuestas NPS, evaluación de programas e instructores; ~2,500 usuarios | Hallazgo 17-sep-2026: existe una automatización real SEA→Qualtrics→SharePoint documentada en Bizagi (ver columna Integraciones #). | AP21: VEC | AQ21: 3 | AR21: Encuesta Cliente VEC (posible origen de datos NPS) | AS21: Parcial / relacionada
A22: 19 | B22: Si | E22: 5170-VPA-001-TRXC | F22: Accredible (VEC) | G22: Emisión de credenciales y badges digitales para egresados de programas VEC | H22: 18. APF Ecosistema Digital | I22: ECD03- APF Vivencia y Gestión del Aprendizaje | J22: Claudia Arellano (claudia.arellano@tec.mx) | K22: Claudia Arellano Arciga, María del Rosario Pérez Sánchez y Cristina Martínez (equipo de escolares). | L22: j.leon@tec.mx DISPUTADO en sesión S-049 (17-sep-2026): Julieta Adriana León López no acepta ser responsable funcional única de Accredible — no administra la plataforma, no tiene acceso administrativo y no define requerimientos para todas las áreas usuarias. Su equipo (Excelencia Académica y Normatividad) solo valida lineamientos institucionales y autoriza cambios normativos para la emisión de documentos. La plataforma es usada de forma independiente por múltiples áreas (Educación para el Desarrollo, Centro de Idiomas, EGADE, entre otras). Responsable Funcional Institucional: pendiente de definir (ver si existe un Product Owner institucional o un esquema compartido entre áreas). | M22: rosario_perez@tec.mx Confirmado en sesión S-049 (17-sep-2026): María del Rosario Pérez Sánchez funge como administradora operativa de Accredible para la VPAF — gestiona configuraciones, usuarios, permisos, grupos, insignias y documentos, sin acceso al código fuente ni a la infraestructura del proveedor (administración técnica, infraestructura y operación base son responsabilidad del proveedor Accredible, naturaleza SaaS). | N22: rosario_perez@tec.mx -> se entregará a Uman Diez | O22: rosario_perez@tec.mx -> se entregará a Uman Diez | P22: Accredible (plataforma externa) | Q22: SaaS | R22: Cloud-SaaS | S22: Accredible (plataforma externa) | T22: https://educacioncontinua.tec.mx/ | U22: No aplica (SaaS sin ambiente de desarrollo gestionado por VPAF) | V22: No aplica (SaaS sin ambiente de preproducción gestionado por VPAF) | W22: No aplica (SaaS con actualización continua del proveedor) | X22: Sin información | Y22: Sujeto a contrato con Accredible; pendiente de confirmar con el administrador del contrato | Z22: 1,200 usuarios | AA22: 0 | AB22: 0 | AC22: 0 | AD22: 0 | AE22: High | AF22: 3 | AH22: =IF(AND(AF22>=3,AG22>=3),"Invest",IF(AND(AF22>=3,AG22<3),"Migrate",IF(AND(AF22<3,AG22>=3),"Tolerate","Eliminate"))) -> Migrate | AI22: 46251 | AJ22: 46616 | AK22: Active | AL22: 1 | AM22: Confidential | AN22: Datos personales de egresados (LFPDPPP): nombre, matrícula y programa acreditado. Plataforma SaaS externa; credenciales verificables públicamente por diseño. | AO22: Emisión de credenciales y badges digitales para egresados de programas VEC Registro VPAF: responsables Claudia Arellano y María del Rosario Pérez. Descripción registrada: "Expedición de credenciales digitales". CONFLICTO DE DISPOSICIÓN: el registro de arquitectura del Tec (Catálogos ED, hoja 84, corte 01/05/2026) lo marca "En producción" con estrategia "Mantener", mientras este inventario captura "Migrate". Pendiente de resolver con Arturo. El mismo registro clasifica su confidencialidad como Estándar; aquí se captura Confidential por tratarse de datos de egresados con matrícula. Se sostiene el criterio más restrictivo. La wiki del Tec lo lista con institución "Aprendizaje para el futuro" y estatus "Por implementar", lo que contradice el "En producción" del catálogo de arquitectura. Validar cuál es el estado vigente. Dato de contrato (Template contratos_11Sep26_V1.xlsx): Vendor = EdInvent, Inc., dba Accredible; Contract Administrator = Jorge Alberto González López; Approver = Carmen Isabel Reyes Peraza. | AP22: VEC | AQ22: 4 | AR22: DIR-008 - Mis insignias - Portal-Accredible | AS22: Confirmada
A23: 20 | B23: Si | E23: 5086-HTI-001-TRXC | F23: Formulario U4O | G23: Registro y pago para maestrías y diplomados; integra SEA y Salesforce | H23: 03. Facultad | I23: FAC02. Desarrollo de Facultad | J23: Sin información | K23: Proveedor externo: responsable del soporte técnico. María del Rosario Pérez: administra contenido y estructura del formulario. / Gama Logistica | L23: Larisa Díaz y Ana Karen Jimenez | M23: Rosario Perez | N23: Rosario Perez / Gama Logistica | O23: Rosario Perez / Gama Logistica | P23: Proveedor externo (web propietaria) | Q23: Custom Development | R23: Cloud-SaaS | S23: Proveedor externo (web propietaria) | T23: Sin información | U23: https://apps.powerapps.com/play/e/90c43019-1fbe-42ac-95f3-6b777a4cb3a5/a/ff1774e7-0984-48a2-a113-b3812552f586?tenantId=c65a3ea6-0f7c-400b-8934-5a6dc1705645&hint=82fc623d-61c4-4a5a-93e2-48e8edb99d50&sourcetime=1753399355042 | V23: https://apps.powerapps.com/play/e/ffa54977-61ce-49a1-b018-648e027b3954/a/5daa3046-8ec8-40b5-855b-c6f0ce2d3c3e?tenantId=c65a3ea6-0f7c-400b-8934-5a6dc1705645&hint=5656ca9d-cbe0-415c-9662-9b95db11083c&sourcetime=1753399384248 | W23: Sin información | X23: Sin información | Y23: Sin información | Z23: El resultado global muestra un total de 31,699 registros, de los cuales 28,330 corresponden a registros únicos dentro del período analizado. Desglosado por año: -Año 2025: 22,777 registros totales y 20,294 registros únicos en el período. -Año 2024: 8,922 registros totales y 8,423 registros únicos en el período. | AA23: 0 | AB23: 0 | AC23: 0 | AD23: 0 | AE23: High | AF23: 4 | AH23: =IF(AND(AF23>=3,AG23>=3),"Invest",IF(AND(AF23>=3,AG23<3),"Migrate",IF(AND(AF23<3,AG23>=3),"Tolerate","Eliminate"))) -> Migrate | AI23: Sin información | AJ23: Sin información | AK23: Active | AL23: Sin información | AM23: Sin información | AN23: Sin información | AO23: Registro y pago para maestrías y diplomados; integra SEA y Salesforce | AP23: VEC | AQ23: 4 | AR23: Solicitud de Inscripción SF - SEA (integración Salesforce-SEA) | AS23: Parcial / relacionada
A24: 21 | B24: Si | E24: Sin información | F24: Portal de registro y pago | G24: Registro y pago de participantes externos; aprovisiona a SEA | H24: Sin información | I24: Sin información | J24: Sin información | K24: Bryan Moreno (externo) la empresa es Gama Logistica - proveedor Ernesto Martinez Sesión S-050 (17-sep-2026): se identificó a María del Rosario Pérez Sánchez como posible responsable técnica, pendiente de validación formal — dato distinto al ya registrado (Bryan Moreno / Gama Logística); queda como discrepancia sin resolver hasta validación formal con el equipo. | L24: Ricardo Lopez Sesión S-050 (17-sep-2026): Ricardo López Strozzi (lopez.ricardo@tec.mx) identificado como responsable funcional principal, pendiente de validación formal. | M24: rosario_perez@tec.mx | N24: rosario_perez@tec.mx / Gama Logistica Operación diaria confirmada en sesión S-050 (17-sep-2026): ambiente PPRD a cargo de Marco Gerardo Chavira Pérez; Producción a cargo de Ernesto Martínez Arriaga. Soporte especializado: proveedor del habilitador (Gama Logística). No existe una gran cantidad de usuarios administrando el Portal — solo estas dos personas tienen acceso operativo directo. | O24: rosario_perez@tec.mx / Gama Logistica | P24: Proveedor externo (web custom) | Q24: Custom Development | R24: Cloud-SaaS Infraestructura confirmada (Diagrama de infraestructura.drawio, carpeta 'Evidencia y platicas/Portal Registro y Pagos'): AWS Cloud para el Portal de registro y Pago (unidades de cómputo separadas Producción/Desarrollo; autenticación con servicios externos Facebook y Gmail; Cron jobs; 2 bases de datos MySQL), conectado vía Internet al lado de SEA en Azure Cloud (unidad de cómputo Producción, depende de Salesforce; base de datos MariaDB). | S24: Proveedor externo (web custom) Servicios externos identificados en el mismo diagrama: Tec.Pay (pasarela de cobros interna de la institución; depende internamente de Salesforce, OpenPay y Flywire) y un sistema "Middleware" interno desarrollado por el equipo del TEC que ejecuta flujos de trabajo en HubSpot para las notificaciones por correo (recordatorio de inscripción y generación de factura, ambos disparados por Cron). | T24: checkout.tec.mx (mencionado como origen del flujo de pago en los diagramas de secuencia de compra y venta: 'Portal: checkout.tec.mx - solicitudId/origenConexion'). No se confirmó si es la URL pública completa del propio Portal de Registro y Pago o solo del paso de checkout. Confirmado por los diagramas de secuencia reales (Diagrama de secuencia - SEA/ECOMMERCE/EGADE/CEDIAM.txt, mismo folder): checkout.tec.mx SÍ es el paso de checkout/pago del flujo ("Portal: checkout.tec.mx - solicitudId/origenConexion"), usado tanto por el flujo directo de e-commerce como por los flujos asistidos por asesor de SEA y EGADE, vía APIs Gama Logística → Tec.Pay → SEA. | U24: Sin información | V24: Sin información | W24: Sin información | X24: Sin información | Y24: Sin información | Z24: El análisis global muestra un total de 139,381 registros, de los cuales 117,788 son únicos, lo que representa un 15% de registros duplicados. Desglosado por año: -2025: 26,252 registros totales, 23,870 únicos y 9% duplicados. -2024: 27,884 registros totales, 25,537 únicos y 8% duplicados. -2023: 24,092 registros totales, 21,719 únicos y 10% duplicados. -2022: 24,317 registros totales, 22,367 únicos y 8% duplicados. -2021: 21,674 registros totales, 19,978 únicos y 8% duplicados. -2020: 13,655 registros totales, 12,225 únicos y 10% duplicados. -2019: 1,507 registros totales, 1,355 únicos y 10% duplicados. | AA24: 0 | AB24: 0 | AC24: 0 | AD24: 0 | AE24: Medium | AF24: 3 | AH24: =IF(AND(AF24>=3,AG24>=3),"Invest",IF(AND(AF24>=3,AG24<3),"Migrate",IF(AND(AF24<3,AG24>=3),"Tolerate","Eliminate"))) -> Migrate | AI24: Sin información | AJ24: Sin información | AK24: Active | AL24: 3 confirmadas por diagrama de flujo (Bizagi, "Sincronización con portal de registro y pago", autor Israel Romero, v1.0, abr-2026): (1) SEA — creación y publicación de programas, sincronización bidireccional; (2) TLG — consulta horaria de alumnos ("cada hora"); (3) Salesforce — como parte del flujo de venta (Página de maestrías / oferta). No se localizó documentación de integración con VTEX para este habilitador específico. Endpoints reales confirmados por los diagramas de secuencia (mermaid, carpeta 'Evidencia y platicas/Portal Registro y Pagos'): registro/checaExisteEmail, registro/checaBeca, participantes/guardar-usuario, educacionejecutiva/itesm/json/checkusuario, educacionejecutiva/itesm/json/verificarCupo, educacionejecutiva/itesm/json/guardarSolicitud, educacionejecutiva/itesm/json/guardarPago, checkout/regreso_a_tienda (webhook "aviso_transaccion" de Tec.Pay). Además existen 2 canales alternos de adquisición EN ANÁLISIS/DISEÑO (no confirmados en producción): (1) Shopify — requeriría un WebHook nuevo hacia SEA y decidir entre la pasarela propia de Shopify (cobra comisión) o integrar Tec.Pay vía un intermediario del proveedor (Merlioni); (2) VTEX Marketec — ya cuenta con pasarela propia equivalente a Tec.Pay y comunica directamente a Salesforce/Banner, con TEC Milenio como ejemplo de implementación de referencia. | AM24: Sin información | AN24: Sin información | AO24: Registro y pago de participantes externos; aprovisiona a SEA | AP24: VEC | AQ24: 3 | AR24: No se encontró carpeta correspondiente en el índice de SharePoint | AS24: No encontrada
A25: 22 | E25: 5145-HTI-001-TRXC | F25: Página de oferta VEC | G25: Sitio público con oferta educativa (diplomados, certificaciones, maestrías) | H25: 15. Aprendizaje para el futuro | I25: ATV03-1. Atracción y Venta | J25: Carlos Franco (cfrancor@tec.mx) — el registro VPAF lo marca como responsable de "Página de oferta" | K25: Tanto interno como proveedor (Carlos Alberto Martínez) | L25: cfrancor@tec.mx | M25: carlos.msam@tec.mx | N25: cfrancor@tec.mx | O25: Sin información | P25: Ruby on Rails (proveedor externo) | Q25: Custom Development | R25: Cloud-SaaS | S25: Ruby on Rails (proveedor externo) | T25: https://maestriasydiplomados.tec.mx | U25: Sin información | V25: Sin información | W25: Sin información | X25: Sin información | Y25: 2027-11-29 | Z25: No se tiene el volumen de usuarios ya que no tienen acceso | AA25: 0 | AB25: 0 | AC25: 0 | AD25: 0 | AE25: Medium | AF25: 3 | AG25: 4 | AH25: =IF(AND(AF25>=3,AG25>=3),"Invest",IF(AND(AF25>=3,AG25<3),"Migrate",IF(AND(AF25<3,AG25>=3),"Tolerate","Eliminate"))) -> Invest | AI25: 46251 | AJ25: 46616 | AK25: Active | AL25: 2 | AM25: Public | AN25: Sitio público sin autenticación ni captura de datos personales. Contenido de oferta educativa sujeto a lineamientos de marca institucional. | AO25: Sitio público con oferta educativa (diplomados, certificaciones, maestrías) Registro VPAF: responsable Carlos Franco (cfrancor@tec.mx). Descripción registrada: "Sitio público con oferta educativa VEC", sin login. CONFLICTO DE DISPOSICIÓN: el catálogo de arquitectura del Tec (Catálogos ED, hoja 84) registra el "Portal de Mestrias y Diplomados" con estrategia "Eliminar", ajuste de negocio Malo y ajuste de TI Malo, mientras este inventario captura "Invest" con ST 4. Pendiente de resolver con Arturo. Vigencia documentada hasta el 29/11/2027. El Portal Unificado lo reemplaza (Go Live octubre 2026) y el Portal de Compra y Pago asociado vence el 13/10/2026. Integra Algolia como motor de búsqueda del portal. Confianza de correspondencia Media-Alta con el habilitador 5145-HTI-001-TRXC: requiere validación con el Tec antes de darlo por bueno. Responsable de soporte pendiente: no aparece en la wiki ni en el registro VPAF. ⚠ Verificar: ID Habilitador también asignado a fila 26 ("Programa Educación Continua (MiTec)"). | AP25: VEC | AQ25: 3 | AR25: Flujo de búsqueda de productos (Página de oferta integra Algolia, según Notas) | AS25: Parcial / relacionada
A26: 23 | E26: 5145-HTI-001-TRXC | F26: Programa Educación Continua (MiTec) | G26: Conexión con maestrías y diplomados desde portal institucional MiTec | H26: 15. Aprendizaje para el futuro | I26: ATV03-1. Atracción y Venta | J26: Ulises (solo nombre de pila; fuente: Correspondencia_Aplicaciones_APM_vs_Habilitadores.xlsx) | K26: Claudia Arellano Arciga | L26: cfrancor@tec.mx | M26: carlos.msam@tec.mx | N26: cfrancor@tec.mx | O26: oscar.rdz@tec.mx | P26: Microsoft Azure | Q26: Custom Development | R26: Cloud-SaaS | S26: Frontend integrado a MiTec (Azure) | T26: https://maestriasydiplomados.tec.mx | U26: Sin información | V26: Sin información | W26: Sin información | X26: Sin información | Y26: Sin información | Z26: No aplica ya que solo los usuarios entran y se dirigen a las opciones que les interesa consultar | AA26: 0 | AB26: 0 | AC26: 0 | AE26: Medium | AF26: 3 | AG26: 4 | AH26: =IF(AND(AF26>=3,AG26>=3),"Invest",IF(AND(AF26>=3,AG26<3),"Migrate",IF(AND(AF26<3,AG26>=3),"Tolerate","Eliminate"))) -> Invest | AI26: Sin información | AJ26: Sin información | AK26: Active | AL26: Sin información | AM26: Sin información | AN26: Sin información | AO26: Conexión con maestrías y diplomados desde portal institucional MiTec ⚠ Verificar: ID Habilitador también asignado a fila 25 ("Página de oferta VEC"). | AP26: VEC | AQ26: 3 | AR26: No se encontró carpeta correspondiente en el índice de SharePoint | AS26: No encontrada
A27: 24 | B27: Si | E27: 5138-HTI-001-TRXC | F27: DED (portales VEC) | G27: Cuatro portales para Educación para el Desarrollo: registro, pago y entrega de contenidos | H27: 15. Aprendizaje para el futuro | I27: ATV04. Gestión de la Oferta | J27: Daniela de la Rosa (líder de proyecto) — así aparece en el registro VPAF | K27: Equipo DED Neotek (soporte Drupal) - Dev Team Head Bryan Moreno | L27: Karina Martinez | M27: Rosario Perez | N27: Neotek (soporte Drupal) | O27: Neotek (soporte Drupal) | P27: Drupal | Q27: Custom Development | R27: Cloud-SaaS | S27: Drupal (proveedor Neotec) + sitios reconstruidos | T27: https://www.centroscomunitariosdeaprendizaje.org.mx; https://www.formandoformadores.org.mx; https://www.aprendizajeverde.net | U27: Sin información | V27: Sin información | W27: Sin información | X27: CVA desde 2010 / FF desde 2015 / AV desde 2012 | Y27: Sin información | Z27: CVA ~710,000 / FF 42,250 / AV 35,350 / Más Sociedad sin usuarios | AA27: 0 | AB27: 0 | AC27: 0 | AD27: 0 | AE27: High | AF27: 4 | AG27: 4 | AH27: =IF(AND(AF27>=3,AG27>=3),"Invest",IF(AND(AF27>=3,AG27<3),"Migrate",IF(AND(AF27<3,AG27>=3),"Tolerate","Eliminate"))) -> Invest | AI27: 46251 | AJ27: 46616 | AK27: Active | AL27: 4 | AM27: Confidential | AN27: Datos personales de participantes (LFPDPPP) y datos de pago. Portales públicos con registro. Desarrollo y soporte a cargo de proveedor externo (Neotek): aplica cláusula de tratamiento de datos por terceros. | AO27: Cuatro portales para Educación para el Desarrollo: registro, pago y entrega de contenidos Registro VPAF: Daniela de la Rosa (líder de proyecto) y Jesús Alejandro Medina (técnico). Proveedor externo Neotek. El registro también lista "Superate" como ecosistema educativo en línea de la Dirección de Educación para el Desarrollo, con ~150 usuarios internos mensuales y 30-40k externos mensuales. El Centro Virtual de Aprendizaje aparece en VPAF con 1,200,000 usuarios históricos, consistente con los ~710,000 capturados aquí para CVA. DISCREPANCIA DE ALCANCE: este renglón declara cuatro portales, pero en la wiki del Tec solo se localizaron tres bajo el habilitador 5138-HTI-001-TRXC. El cuarto ("Más Sociedad") aparece aquí sin usuarios registrados. Validar con el Tec si forma parte del mismo habilitador o si debe registrarse aparte. La clasificación de datos y las etiquetas de cumplimiento aplican al conjunto de portales; el tratamiento de datos personales está delegado a proveedor externo. ⚠ Nota v16: se descartó el vínculo a la carpeta "Presentaciones de avance DED" — es coincidencia de siglas (gobierno del proyecto Ecosistema Digital), no documentación de este aplicativo (Educación para el Desarrollo). | AP27: VEC | AQ27: 4 | AR27: No se encontró carpeta correspondiente en el índice de SharePoint | AS27: No encontrada
A28: 25 | E28: 0470-HTI-001-TRXC | F28: Marketplace de Talento | G28: Conecta a prospectos egresados con empleadores | H28: Graduway | I28: Sin información | J28: Sin información | K28: Sin información | L28: Sin información | M28: Sin información | N28: Sin información | O28: Sin información | P28: Sin información | T28: Sin información | U28: Sin información | V28: Sin información | W28: Sin información | X28: Sin información | Z28: Sin información | AE28: Medium | AH28: Eliminate | AI28: Sin información | AK28: Sin información | AL28: Sin información | AM28: Sin información | AO28: VEC | AP28: 3 | AQ28: 3 | AR28: No se encontró carpeta correspondiente en el índice de SharePoint | AS28: No encontrada
E29: 5147-HTI-001-TRXC | H29: Marketplace de Socios Formadores | I29: Sin información | J29: Sin información | K29: Sin información | L29: daniel_ayala@tec.mx | M29: gerardo.suarez@tec.mx | N29: mariano_uriostegui@tec.mx | O29: mariano_uriostegui@tec.mx | P29: Sin información | Q29: Custom Development | S29: Node.js;#8;#Java;#9 | T29: https://www.mpstec.mx/ | U29: Sin información | V29: Sin información | W29: Sin información | X29: Sin información | Z29: Sin información | AE29: Medium | AH29: Eliminate | AI29: Sin información | AK29: Sin información | AL29: Sin información | AM29: Sin información | AN29: Plataforma para conectar ácademicos con Socios Formadores para colaborar en proyectos. | AO29: VEC | AP29: 3
